Workbook

Sheet Leia-me
B2: PLANO ON-TRADE RIO — FONTE ÚNICA DE PLANEJAMENTO
B3: Ago–Dez 2026 · documento de trabalho do time · preencher e atualizar na cadência semanal (WAR Rio)
B5: Como usar
B6: • | C6: As células em AMARELO são as que o time preenche. As brancas são referência já vinda do plano.
B7: • | C7: Colunas com seta (▾) têm lista suspensa — clique e escolha, não digite livre.
B8: • | C8: Cada linha precisa terminar com: estágio, próximo passo, prazo e — quando aplicável — decisão.
B9: • | C9: Regra de decisão: toda iniciativa fecha em Manter, Corrigir, Escalar, Renegociar ou Parar.
B10: • | C10: Nada vira compromisso oficial sem owner, prazo, orçamento e evidência.
B11: • | C11: A primeira linha de cada aba é um EXEMPLO (fundo bege) — apague antes de usar de verdade.
B13: Legenda de status
B14: CONFIRMADO | C14: Decisão tomada, contrato ou informação formal — executar.
B15: ALINHADO | C15: Direcionamento acordado, falta formalizar — planejar e confirmar.
B16: EM NEGOCIAÇÃO | C16: Conversa ativa com casa/parceiro — manter owner e próximo passo.
B17: EM AVALIAÇÃO | C17: Alternativa considerada, ainda não escolhida — comparar e decidir.
B18: HIPÓTESE | C18: Recomendação para análise — testar antes de oficializar.
B19: PENDENTE DE DADOS | C19: Falta volume, custo, contrato ou evidência — não escalar.
B21: Ownership
B22: Business Owner | C22: Casa, volume, contrapartidas, recompra e resultado comercial.
B23: Brand Owner | C23: Conceito, experiência, linguagem, comunidade e conteúdo.
B24: Project Owner | C24: Cronograma, integração, produção, execução e fechamento.
B26: Painel — contas por status
B27: CONFIRMADO | C27: =COUNTIF('Contas & Rota'!$F$4:$F$200,"CONFIRMADO") -> 1
B28: ALINHADO | C28: =COUNTIF('Contas & Rota'!$F$4:$F$200,"ALINHADO") -> 8
B29: EM NEGOCIAÇÃO | C29: =COUNTIF('Contas & Rota'!$F$4:$F$200,"EM NEGOCIAÇÃO") -> 9
B30: EM AVALIAÇÃO | C30: =COUNTIF('Contas & Rota'!$F$4:$F$200,"EM AVALIAÇÃO") -> 3
B31: HIPÓTESE | C31: =COUNTIF('Contas & Rota'!$F$4:$F$200,"HIPÓTESE") -> 5
B32: PENDENTE DE DADOS | C32: =COUNTIF('Contas & Rota'!$F$4:$F$200,"PENDENTE DE DADOS") -> 0
B33: Total de contas | C33: =COUNTA('Contas & Rota'!$A$4:$A$200) -> 26
B36: Abas de execução (novas)
B37: Radar ON6 Rio | C37: Contas ranqueadas por Gap ON6 com ação sugerida (dados reais do BAM).
B38: Rota Semanal | C38: Planejador de rota seg–sex; o BA escolhe os focos a partir do Radar.
B39: Pipeline Contratos | C39: Funil CT-### (Mapeado→Fechado) + faixas de volume e investimento.
B41: Aprovação Contratos | C41: Calculadora de investimento (R$20/R$30/gfa, 25% TM) + pipeline RJ+SP pré-carregado.
B42: Parâmetros Contrato | C42: Perfis, energia, prioridade, faixas de volume e arquétipos de investimento.
B44: Carteira Julia | C44: 52 contas do Rio (base "Amanda Vanderlei" no sistema) que a Julia assume ao entrar na vaga de BA Rio.

Sheet Contas & Rota
A1: IDENTIDADE | G1: NEGÓCIO | L1: GESTÃO
A2: Conta | B2: Frente ▾ | C2: Território / bairro | D2: Papel ▾ | E2: Owner ▾ | F2: Status ▾ | G2: Volume atual (gf/mês) | H2: Potencial (gf/mês) | I2: Contrato ▾ | J2: Investimento | K2: Custo/gf | L2: Estágio ▾ | M2: Próximo passo | N2: Prazo | O2: Decisão ▾
A3: (exemplo) Casa X | B3: Hotzone | C3: Botafogo | D3: Conversão | E3: Julia | F3: EM NEGOCIAÇÃO | G3: 120 | H3: 300 | I3: Não | J3: 6000 | K3: 25 | L3: Negociação | M3: Fechar cardápio e treino de brigada | N3: 30/08/2026 | O3: Escalar
A4: Bosque Bar | B4: Castelo | C4: Gávea | D4: Volume | E4: Jerry | F4: CONFIRMADO | I4: Sim
A5: Aldeia Lagoa | B5: Hotzone | C5: Lagoa | D5: Âncora | F5: ALINHADO | I5: Sim
A6: Caza Lagoa | B6: Hotzone | C6: Lagoa | D6: Âncora | F6: ALINHADO | I6: Sim
A7: Elena | B7: Hotzone | C7: Horto | D7: Imagem | F7: EM NEGOCIAÇÃO | I7: Não
A8: Eleninha | B8: Hotzone | C8: Horto | D8: Volume | F8: EM NEGOCIAÇÃO | I8: Não
A9: Parque Bar | B9: Hotzone | C9: Horto | D9: Volume | F9: EM NEGOCIAÇÃO | I9: Não
A10: Araá | B10: Área Turística | C10: Morro da Urca | D10: Imagem | F10: EM NEGOCIAÇÃO | I10: Não
A11: D-Edge Rio | B11: Alta energia | C11: Saúde | D11: Imagem | F11: EM NEGOCIAÇÃO | I11: Não
A12: Escuta | B12: Cena | C12: Botafogo | D12: Imagem | F12: EM NEGOCIAÇÃO | I12: Não
A13: Fala | B13: Cena | C13: — | D13: Imagem | F13: EM NEGOCIAÇÃO | I13: Não
A14: Chora Café | B14: Cena | C14: — | D14: Imagem | F14: EM AVALIAÇÃO | I14: Não
A15: Destilaria Maravilha | B15: Cena | C15: Rua do Senado | D15: Ritual | F15: EM NEGOCIAÇÃO | I15: Não
A16: Mercado Central | B16: Cena | C16: — | D16: Imagem | F16: EM AVALIAÇÃO | I16: Não
... A29: Portal | B29: Hotzone | C29: Centro / Lapa | D29: Conversão | F29: ALINHADO | I29: Não

Sheet Contratos
A1: CONTRATO | G1: EXECUÇÃO & RESULTADO | L1: DECISÃO
A2: Conta | B2: Owner ▾ | C2: Status ▾ | D2: Vigência início | E2: Vigência fim | F2: Investimento total | G2: Meta volume (gf) | H2: Contrapartidas | I2: Entregues? ▾ | J2: Recompra 15/30d ▾ | K2: Próximo review | L2: Decisão ▾ | M2: Observações
A3: (exemplo) Casa X | B3: Jerry | C3: CONFIRMADO | D3: 01/08/2026 | E3: 31/12/2026 | F3: 24000 | G3: 1500 | H3: Menu, -18°C, 2 ativações/mês | I3: Parcial | J3: Pendente | K3: 15/09/2026 | L3: Manter | M3: Renovar se recompra > baseline
A4: Bosque Bar | B4: Jerry | C4: CONFIRMADO
A5: Aldeia Lagoa | C5: ALINHADO
A6: Caza Lagoa | C6: ALINHADO
A7: Soga Beach | C7: EM NEGOCIAÇÃO

Sheet Tailor Made & Projetos
A1: PROJETO | F1: FUNIL DE 3 GATES | I1: ENTREGA
A2: Projeto / conta | B2: Tipo ▾ | C2: Owner ▾ | D2: Sponsor ▾ | E2: Status ▾ | F2: Gate 1 Conceito/Budget ▾ | G2: Gate 2 Produção/Log. ▾ | H2: Gate 3 Instalação/Aceite ▾ | I2: Fornecedor | J2: Orçamento | K2: Data entrega | L2: Critério de conclusão | M2: Próximo passo
A3: (exemplo) Ativação Casa X | B3: Ativação | C3: Iasmin | D3: Bruno | E3: ALINHADO | F3: OK | G3: Em curso | H3: Aberto | I3: Rigarr | J3: 15000 | K3: 20/09/2026 | L3: Instalado + treinado + evidência | M3: Fechar orçamento com fornecedor
A4: Tailor Made Bosque | B4: Tailor Made | C4: Iasmin | D4: Bruno | E4: CONFIRMADO | I4: Rigarr | L4: Material + brigada + produto + ritual + evidência
A5: Jägermeister Orange (testes) | B5: Ativação | D5: Bruno | E5: CONFIRMADO | K5: 05–06/08 | L5: Serve, preço e aderência definidos | M5: Confirmar casa substituta do Canastra
A6: Shots & Friends | B6: Plataforma | D6: Marketing | E6: ALINHADO | L6: Casa + artista + rights + baseline definidos | M6: Confirmar calendário e casas
A7: Night Embassy | B7: Evento | D7: Marketing | E7: ALINHADO | K7: Dezembro | L7: Modelo, local, curadoria e owners definidos | M7: Definir tensão cultural e formato
A8: Dark Xmas | B8: Evento | D8: Marketing | E8: EM AVALIAÇÃO | K8: Dezembro | L8: Narrativa própria + parceiros reconhecidos | M8: Definir escopo
A9: Mesa Jäger (Feierstarters) | B9: Plataforma | C9: Community | D9: Marketing | E9: ALINHADO | L9: Mecânica conciliada + casas + recorrência | M9: Conciliar mecânica antes de comunicar
A10: Board Visit | B10: Evento | C10: Bruno | D10: Bruno | E10: CONFIRMADO | I10: Interfood | K10: 26–27/08 | L10: Contas prontas, -18°C, ON6 e rota validada | M10: Validar rota final e fim de tarde

Sheet Account Excellence
A1: CONTA | C1: CHECKLIST DE EXECUÇÃO | K1: RESULTADO
A2: Conta | B2: Owner ▾ | C2: Disponibilidade ▾ | D2: -18°C ▾ | E2: Perfect Serve ▾ | F2: Cardápio ▾ | G2: ON6 ▾ | H2: Brigada treinada ▾ | I2: Visibilidade ▾ | J2: Evidência ▾ | K2: Perfect Outlet ▾ | L2: Gap principal | M2: Próximo passo
A3: (exemplo) Casa X | B3: Julia | C3: Sim | D3: Sim | E3: Parcial | F3: Sim | G3: Parcial | H3: Não | I3: Sim | J3: Sim | K3: Não | L3: Brigada sem treino | M3: Agendar treino e revisar ON6
A4: Bosque Bar | B4: Julia
A5: Aldeia Lagoa | C5: Sim | D5: Sim | E5: Sim | F5: Sim | G5: Parcial | H5: Sim | I5: Sim | J5: Sim | K5: Não | L5: Ativação e preço
A6: Caza Lagoa | C6: Sim | D6: Sim | E6: Sim | F6: Sim | G6: Parcial | H6: Sim | I6: Sim | J6: Sim | K6: Não | L6: Ativação e preço
A7: Macuna | C7: Sim | D7: Sim | E7: Sim | F7: Sim | G7: Parcial | H7: Não | I7: Sim | J7: Sim | K7: Não | L7: Treinamento
A8: Brizza | C8: Sim | D8: Sim | E8: Sim | F8: Sim | G8: Parcial | H8: Não | I8: Sim | J8: Sim | K8: Não | L8: Ativação e treinamento
A9: Madre de Capotá | C9: Sim | D9: Sim | E9: Sim | F9: Sim | G9: Parcial | H9: Não | I9: Sim | J9: Sim | K9: Não | L9: Ativação e treinamento
A10: Vizinha 123 | C10: Sim | D10: Sim | E10: Sim | F10: Sim | G10: Parcial | H10: Sim | I10: Sim | J10: Sim | K10: Não | L10: Ativação e preço
A11: Portal | C11: Sim | D11: Sim | E11: Sim | F11: Sim | G11: Parcial | H11: Não | I11: Sim | J11: Sim | K11: Não | L11: Ativação e treinamento
A12: Pato com Laranja
A22: ON6 = 6 pontos → Perfect Outlet = 6/6: | B22: 1 Serviço perfeito | C22: 2 Temperatura (-18°C) | D22: 3 Frio / tap / óculos gelados | E22: 4 Visibilidade no PDV | F22: 5 Cardápio / menu / quadro | G22: 6 Ativação ou treinamento

Sheet Tracker de Decisões
A1: DECISÃO | F1: ENCAMINHAMENTO
A2: Decisão / tema | B2: Tipo ▾ | C2: Owner ▾ | D2: Participantes | E2: Status ▾ | F2: Evidência / próximo passo | G2: Prazo | H2: Decisão final
A3: (exemplo) Definir owner da Orla | B3: Estrutural | C3: Bruno | D3: Jerry | E3: Em andamento | F3: Comparar capacidade de rota | G3: 30/08/2026 | H3: Owner: Iasmin
A4: Tailor Made Bosque | B4: Crítica agosto | C4: Bruno | D4: Jerry, Iasmin | E4: Aberta | F4: Cronograma, orçamento, fornecedor, instalação e aceite
A5: Cariocarga (logística) | B5: Crítica agosto | C5: Bruno | D5: Iasmin | E5: Aberta | F5: Reunião, SLA, custo, entrega, reversa e piloto
A6: Substituta do Canastra (Orange) | B6: Crítica agosto | C6: Bruno | D6: Jerry, Marketing | E6: Aberta | F6: Confirmar casa, público, data, operação e custo
A7: Rota final do board | B7: Crítica agosto | C7: Bruno | D7: Jerry | E7: Aberta | F7: Validar sequência — não inventar horários
A8: Fim de tarde do board | B8: Crítica agosto | C8: Bruno | E8: Aberta | F8: Pato, Soga ou Morro da Urca; papel de Teremana
A9: Casas de Botafogo (board) | B9: Crítica agosto | C9: Jerry | D9: Julia | E9: Aberta | F9: Programação, execução e narrativa
A10: Shots & Friends no Aldeia | B10: Crítica agosto | C10: Bruno | D10: Marketing, Jerry | E10: Aberta | F10: Confirmar formato, artista, produção e convite
A11: Distribuição de carteira | B11: Estrutural | C11: Bruno | D11: Jerry, Iasmin, Julia | E11: Aberta | F11: Distribuir e definir back-up
A12: Reconciliação de dados (fonte única) | B12: Estrutural | C12: Bruno | E12: Aberta | F12: Cruzar BAM, volume, contratos e investimentos
A13: Metas individuais | B13: Estrutural | C13: Bruno | D13: Vitor | E13: Aberta | F13: Pesos, volume, targets e validação com Vitor

Sheet BAM Rio (base)
A1: BASE BAM RIO — recorte 01/07–03/08/2026 · fonte: Report BAM (Jerry) · 51 contas válidas após limpeza (dedupe + remoção de 8 registros fora da praça/BH)
A2: Execução: Listing 86% · Right Price 73% · Visibilidade 71% · Perfect Serve 67% · -18°C 67% · Treinamento 47% · Ativação 41% · PERFECT OUTLET 31% (16/51). Gargalo: ativação e treinamento.
A3: Venue | B3: Bairro | C3: Perfect Serve | D3: -18°C | E3: Visibilidade | F3: Listing | G3: Ativação | H3: Treinamento | I3: Right Price | J3: Efficiency | K3: Perfect Outlet | L3: Última visita
A4: Bar da Cacia | C4: Sim | D4: Sim | E4: Sim | F4: Sim | G4: Não | H4: Sim | I4: Sim | J4: 5/6 | K4: Não | L4: 46237
A5: Distrital | C5: Sim | D5: Sim | E5: Sim | F5: Sim | G5: Sim | H5: Sim | I5: Sim | J5: 6/6 | K5: Sim | L5: 46237
A6: Dome Lounge Bar | C6: Não | D6: Não | E6: Sim | F6: Sim | G6: Não | H6: Não | I6: Não | J6: 2/6 | K6: Não | L6: 46237
A7: Gis Clube | C7: Sim | D7: Sim | E7: Sim | F7: Sim | G7: Sim | H7: Sim | I7: Sim | J7: 6/6 | K7: Sim | L7: 46237
A8: Lab | C8: Sim | D8: Sim | E8: Sim | F8: Sim | G8: Não | H8: Não | I8: Sim | J8: 4/6 | K8: Não | L8: 46237
A9: Mister Rock | C9: Não | D9: Não | E9: Sim | F9: Sim | G9: Sim | H9: Não | I9: Sim | J9: 4/6 | K9: Não | L9: 46237
A10: Obra bar | C10: Sim | D10: Sim | E10: Sim | F10: Sim | G10: Sim | H10: Sim | I10: Não | J10: 5/6 | K10: Não | L10: 46237
A11: casa sapucai | C11: Sim | D11: Sim | E11: Sim | F11: Sim | G11: Sim | H11: Sim | I11: Sim | J11: 6/6 | K11: Sim | L11: 46234
A12: Bar Bukowski - Botafogo | B12: Botafogo | C12: Sim | D12: Sim | E12: Sim | F12: Sim | G12: Sim | H12: Sim | I12: Sim | J12: 6/6 | K12: Sim | L12: 46233
A13: Bato | B13: Botafogo | C13: Não | D13: Não | E13: Não | F13: Não | G13: Não | H13: Não | I13: Não | J13: 0/6 | K13: Não | L13: 46234
A14: Brizza Botafogo | B14: Botafogo | C14: Sim | D14: Sim | E14: Sim | F14: Sim | G14: Não | H14: Não | I14: Sim | J14: 4/6 | K14: Não | L14: 46220
A15: Canatra Rose Botafogo | B15: Botafogo | C15: Sim | D15: Sim | E15: Sim | F15: Sim | G15: Sim | H15: Sim | I15: Sim | J15: 6/6 | K15: Sim | L15: 46220
A16: Cervejaria Madre de CapotÃ¡ | B16: Botafogo | C16: Sim | D16: Sim | E16: Sim | F16: Sim | G16: Não | H16: Não | I16: Sim | J16: 4/6 | K16: Não | L16: 46231
A17: Fonte - Botafogo | B17: Botafogo | C17: Sim | D17: Sim | E17: Sim | F17: Sim | G17: Sim | H17: Sim | I17: Sim | J17: 6/6 | K17: Sim | L17: 46231
A18: La Catedral - Botafogo | B18: Botafogo | C18: Não | D18: Não | E18: Não | F18: Sim | G18: Não | H18: Não | I18: Sim | J18: 2/6 | K18: Não | L18: 46234
A19: Macuna | B19: Botafogo | C19: Sim | D19: Sim | E19: Sim | F19: Sim | G19: Sim | H19: Não | I19: Sim | J19: 5/6 | K19: Não | L19: 46232
A20: Nicks Bar - Botafogo | B20: Botafogo | C20: Não | D20: Não | E20: Sim | F20: Sim | G20: Não | H20: Não | I20: Sim | J20: 3/6 | K20: Não | L20: 46227
A21: Salva Botafogo | B21: Botafogo | C21: Não | D21: Não | E21: Não | F21: Não | G21: Não | H21: Não | I21: Não | J21: 0/6 | K21: Não | L21: 46231
A22: Surreal - Botafogo | B22: Botafogo | C22: Não | D22: Não | E22: Não | F22: Não | G22: Não | H22: Não | I22: Não | J22: 0/6 | K22: Não | L22: 46233
A23: Vizinha 123 | B23: Botafogo | C23: Sim | D23: Sim | E23: Sim | F23: Sim | G23: Não | H23: Sim | I23: Não | J23: 4/6 | K23: Não | L23: 46231
... A54: Baiuca DJ Bar - Santo Cristo | B54: Santo Cristo | C54: Sim | D54: Sim | E54: Sim | F54: Sim | G54: Não | H54: Não | I54: Sim | J54: 4/6 | K54: Não | L54: 46233
A56: REGISTROS FORA DA PRAÇA (remover da base Rio — parecem ser de Belo Horizonte):
A57: Laicos Bar savassi
A58: Caverna do Rock Pub | B58: Barro Preto
A59: mira Bh
A60: Mulligans PUb | B60: Sion
A61: Deputamadre | B61: Floresta
A62: Esquenta | B62: Savassi
A63: Carcamano Rock Club | B63: Barreiro
A64: Loc Savassi | B64: Fincionarios

Sheet Radar ON6 Rio
A1: RADAR ON6 RIO — 51 contas do Jerry ranqueadas por Gap ON6 (pior primeiro). Perfect Outlet = ON6 6/6. Base: Report BAM 01/07–03/08.
A2: Cliente | B2: Bairro | C2: ON6 | D2: Gap | E2: Serviço | F2: Temp. | G2: Frio/tap | H2: Visib. | I2: Cardápio | J2: Ativ/Trein | K2: Perfect Outlet | L2: Ação sugerida
A3: Salva Botafogo | B3: Botafogo | C3: 0/6 | D3: 6 | E3: ✗ | F3: ✗ | G3: ✗ | H3: ✗ | I3: ✗ | J3: ✗ | K3: Não | L3: Fechar: serviço, -18°C
A4: Surreal - Botafogo | B4: Botafogo | C4: 0/6 | D4: 6 | E4: ✗ | F4: ✗ | G4: ✗ | H4: ✗ | I4: ✗ | J4: ✗ | K4: Não | L4: Fechar: serviço, -18°C
A5: Bato | B5: Botafogo | C5: 0/6 | D5: 6 | E5: ✗ | F5: ✗ | G5: ✗ | H5: ✗ | I5: ✗ | J5: ✗ | K5: Não | L5: Fechar: serviço, -18°C
A6: zinga-ipanema | B6: Ipanema | C6: 0/6 | D6: 6 | E6: ✗ | F6: ✗ | G6: ✗ | H6: ✗ | I6: ✗ | J6: ✗ | K6: Não | L6: Fechar: serviço, -18°C
A7: mad brew | B7: Ipanema | C7: 0/6 | D7: 6 | E7: ✗ | F7: ✗ | G7: ✗ | H7: ✗ | I7: ✗ | J7: ✗ | K7: Não | L7: Fechar: serviço, -18°C
A8: Belmonte - Ipanema | B8: Ipanema | C8: 0/6 | D8: 6 | E8: ✗ | F8: ✗ | G8: ✗ | H8: ✗ | I8: ✗ | J8: ✗ | K8: Não | L8: Fechar: serviço, -18°C
A9: La Catedral - Botafogo | B9: Botafogo | C9: 1/6 | D9: 5 | E9: ✗ | F9: ✗ | G9: ✗ | H9: ✗ | I9: ✓ | J9: ✗ | K9: Não | L9: Fechar: serviço, -18°C
A10: JobÃ¡ - Leblon | B10: Leblon | C10: 1/6 | D10: 5 | E10: ✗ | F10: ✗ | G10: ✗ | H10: ✗ | I10: ✓ | J10: ✗ | K10: Não | L10: Fechar: serviço, -18°C
A11: S Bistro do Leme | B11: Leme | C11: 1/6 | D11: 5 | E11: ✗ | F11: ✗ | G11: ✗ | H11: ✗ | I11: ✓ | J11: ✗ | K11: Não | L11: Fechar: serviço, -18°C
A12: Dome Lounge Bar | C12: 2/6 | D12: 4 | E12: ✗ | F12: ✗ | G12: ✗ | H12: ✓ | I12: ✓ | J12: ✗ | K12: Não | L12: Fechar: serviço, -18°C
A13: Xepa Bar | B13: Botafogo | C13: 2/6 | D13: 4 | E13: ✗ | F13: ✗ | G13: ✗ | H13: ✗ | I13: ✓ | J13: ✓ | K13: Não | L13: Fechar: serviço, -18°C
A14: Nicks Bar - Botafogo | B14: Botafogo | C14: 2/6 | D14: 4 | E14: ✗ | F14: ✗ | G14: ✗ | H14: ✓ | I14: ✓ | J14: ✗ | K14: Não | L14: Fechar: serviço, -18°C
A15: Emporio 37 | B15: Ipanema | C15: 2/6 | D15: 4 | E15: ✗ | F15: ✗ | G15: ✗ | H15: ✓ | I15: ✓ | J15: ✗ | K15: Não | L15: Fechar: serviço, -18°C
A16: La Esquina - Lapa | B16: Lapa | C16: 2/6 | D16: 4 | E16: ✗ | F16: ✗ | G16: ✗ | H16: ✓ | I16: ✓ | J16: ✗ | K16: Não | L16: Fechar: serviço, -18°C
A17: Botecos Rios Leme | B17: Leme | C17: 2/6 | D17: 4 | E17: ✗ | F17: ✗ | G17: ✗ | H17: ✗ | I17: ✓ | J17: ✓ | K17: Não | L17: Fechar: serviço, -18°C
A18: Mister Rock | C18: 3/6 | D18: 3 | E18: ✗ | F18: ✗ | G18: ✗ | H18: ✓ | I18: ✓ | J18: ✓ | K18: Não | L18: Fechar: serviço, -18°C
A19: Substation Bar - Copacabana | B19: Copacabana | C19: 3/6 | D19: 3 | E19: ✗ | F19: ✗ | G19: ✗ | H19: ✓ | I19: ✓ | J19: ✓ | K19: Não | L19: Fechar: serviço, -18°C
A20: Ipanema Beach Hostel - Ipanema | B20: Ipanema | C20: 4/6 | D20: 2 | E20: ✓ | F20: ✓ | G20: ✓ | H20: ✗ | I20: ✓ | J20: ✗ | K20: Não | L20: Fechar: visibilidade, ativação/treino
A21: Pura Brasa Ipanema | B21: Ipanema | C21: 4/6 | D21: 2 | E21: ✓ | F21: ✓ | G21: ✓ | H21: ✗ | I21: ✗ | J21: ✓ | K21: Não | L21: Fechar: visibilidade, cardápio
A22: Belmonte - Leblon | B22: Leblon | C22: 4/6 | D22: 2 | E22: ✓ | F22: ✓ | G22: ✓ | H22: ✗ | I22: ✓ | J22: ✗ | K22: Não | L22: Fechar: visibilidade, ativação/treino
A23: O BalcÃ£o do Jobi - Leblon | B23: Leblon | C23: 4/6 | D23: 2 | E23: ✓ | F23: ✓ | G23: ✓ | H23: ✗ | I23: ✓ | J23: ✗ | K23: Não | L23: Fechar: visibilidade, ativação/treino
A24: Lab | C24: 5/6 | D24: 1 | E24: ✓ | F24: ✓ | G24: ✓ | H24: ✓ | I24: ✓ | J24: ✗ | K24: Não | L24: Fechar: ativação/treino
A25: Brizza Botafogo | B25: Botafogo | C25: 5/6 | D25: 1 | E25: ✓ | F25: ✓ | G25: ✓ | H25: ✓ | I25: ✓ | J25: ✗ | K25: Não | L25: Fechar: ativação/treino
A26: Cervejaria Madre de CapotÃ¡ | B26: Botafogo | C26: 5/6 | D26: 1 | E26: ✓ | F26: ✓ | G26: ✓ | H26: ✓ | I26: ✓ | J26: ✗ | K26: Não | L26: Fechar: ativação/treino
A27: Trauma bar - centro | B27: Centro | C27: 5/6 | D27: 1 | E27: ✓ | F27: ✓ | G27: ✓ | H27: ✓ | I27: ✓ | J27: ✗ | K27: Não | L27: Fechar: ativação/treino
A28: Portal | B28: Centro | C28: 5/6 | D28: 1 | E28: ✓ | F28: ✓ | G28: ✓ | H28: ✓ | I28: ✓ | J28: ✗ | K28: Não | L28: Fechar: ativação/treino
A29: Belmonte - Leme | B29: Leme | C29: 5/6 | D29: 1 | E29: ✓ | F29: ✓ | G29: ✓ | H29: ✓ | I29: ✓ | J29: ✗ | K29: Não | L29: Fechar: ativação/treino
A30: Baiuca DJ Bar - Santo Cristo | B30: Santo Cristo | C30: 5/6 | D30: 1 | E30: ✓ | F30: ✓ | G30: ✓ | H30: ✓ | I30: ✓ | J30: ✗ | K30: Não | L30: Fechar: ativação/treino
A31: casa sapucai | C31: 6/6 | D31: 0 | E31: ✓ | F31: ✓ | G31: ✓ | H31: ✓ | I31: ✓ | J31: ✓ | K31: Sim | L31: Perfect Outlet — manter e escalar
A32: Gis Clube | C32: 6/6 | D32: 0 | E32: ✓ | F32: ✓ | G32: ✓ | H32: ✓ | I32: ✓ | J32: ✓ | K32: Sim | L32: Perfect Outlet — manter e escalar
A33: Obra bar | C33: 6/6 | D33: 0 | E33: ✓ | F33: ✓ | G33: ✓ | H33: ✓ | I33: ✓ | J33: ✓ | K33: Não | L33: Perfect Outlet — manter e escalar
A34: Distrital | C34: 6/6 | D34: 0 | E34: ✓ | F34: ✓ | G34: ✓ | H34: ✓ | I34: ✓ | J34: ✓ | K34: Sim | L34: Perfect Outlet — manter e escalar
A35: Bar da Cacia | C35: 6/6 | D35: 0 | E35: ✓ | F35: ✓ | G35: ✓ | H35: ✓ | I35: ✓ | J35: ✓ | K35: Não | L35: Perfect Outlet — manter e escalar
A36: Canatra Rose Botafogo | B36: Botafogo | C36: 6/6 | D36: 0 | E36: ✓ | F36: ✓ | G36: ✓ | H36: ✓ | I36: ✓ | J36: ✓ | K36: Sim | L36: Perfect Outlet — manter e escalar
A37: Fonte - Botafogo | B37: Botafogo | C37: 6/6 | D37: 0 | E37: ✓ | F37: ✓ | G37: ✓ | H37: ✓ | I37: ✓ | J37: ✓ | K37: Sim | L37: Perfect Outlet — manter e escalar
A38: Vuvu - Botafogo | B38: Botafogo | C38: 6/6 | D38: 0 | E38: ✓ | F38: ✓ | G38: ✓ | H38: ✓ | I38: ✓ | J38: ✓ | K38: Sim | L38: Perfect Outlet — manter e escalar
A39: Vizinha 123 | B39: Botafogo | C39: 6/6 | D39: 0 | E39: ✓ | F39: ✓ | G39: ✓ | H39: ✓ | I39: ✓ | J39: ✓ | K39: Não | L39: Perfect Outlet — manter e escalar
A40: Macuna | B40: Botafogo | C40: 6/6 | D40: 0 | E40: ✓ | F40: ✓ | G40: ✓ | H40: ✓ | I40: ✓ | J40: ✓ | K40: Não | L40: Perfect Outlet — manter e escalar
...

Sheet Carteira Julia
A1: CARTEIRA JULIA — 52 contas do Rio (registradas no sistema como BA "Amanda Vanderlei"). Julia assume a vaga de BA Rio e esta carteira. Preencher frente, status e próxima ação (amarelo).
A2: # | B2: Cliente | C2: Bairro | D2: Objetivo | E2: Subcategoria | F2: Energia | G2: Prioridade | H2: Frente | I2: Status | J2: Próxima ação
A3: 1 | B3: All In - Barra da Tijuca | C3: Barra da Tijuca | D3: Imagem | E3: Status | F3: Baixa (2) | G3: Alta | I3: A visitar
A4: 2 | B4: Armazém São Joaquim | D4: Imagem | E4: Creative | F4: Baixa (2) | G4: Alta | I4: A visitar
A5: 3 | B5: Bar da Gema - Maracanã | C5: Maracanã | D5: Volume | E5: N/A | F5: Baixa (2) | G5: Baixa | I5: A visitar
A6: 4 | B6: Bar da Lapa | C6: Lapa | D6: Imagem | E6: Status-Creative | F6: Baixa (2) | G6: Alta | I6: A visitar
A7: 5 | B7: Bartô | D7: Imagem | E7: Creative | F7: Baixa (2) | G7: Alta | I7: A visitar
A8: 6 | B8: Beise | D8: Imagem | E8: Status-Creative | F8: Baixa (2) | G8: Alta | I8: A visitar
A9: 7 | B9: Beneh Gastrobar - Tijuca | C9: Tijuca | D9: Imagem | E9: Status-Creative | F9: Baixa (2) | G9: Alta | I9: A visitar
A10: 8 | B10: Birosca | D10: Imagem | E10: Status | F10: Baixa (2) | G10: Alta | I10: A visitar
A11: 9 | B11: Boa Praça Barra | C11: Barra | D11: Volume | E11: N/A | F11: Baixa (2) | G11: Alta | I11: A visitar
A12: 10 | B12: Bobô Bar | D12: Imagem | E12: Status-Creative | F12: Baixa (2) | G12: Alta | I12: A visitar
A13: 11 | B13: Booze Bar - Lapa | C13: Lapa | D13: Volume | E13: N/A | F13: Baixa (2) | G13: Alta | I13: A visitar
A14: 12 | B14: Boteco da Garrafa | D14: Imagem | E14: Experimenter | F14: Baixa (2) | G14: Alta | I14: A visitar
A15: 13 | B15: Boteco Da Garrafa - Lapa | C15: Lapa | D15: Imagem | E15: Creative | F15: Baixa (2) | G15: Alta | I15: A visitar
A16: 14 | B16: Boteco do Raoni | D16: Imagem | E16: Creative | F16: Baixa (2) | G16: Alta | I16: A visitar
A17: 15 | B17: Boteco Rio's - Méier | C17: Méier | D17: Imagem | E17: Experimenter | F17: Baixa (2) | G17: Baixa | I17: A visitar
A18: 16 | B18: Boteco Rio's - Tijuca | C18: Tijuca | D18: Volume | E18: N/A | F18: Baixa (2) | G18: Alta | I18: A visitar
A19: 17 | B19: Boteco Rios - Barra da Tijuca | C19: Barra da Tijuca | D19: Imagem | E19: Status | F19: Baixa (2) | G19: Alta | I19: A visitar
A20: 18 | B20: Boteco Rios copacabana | C20: Copacabana | D20: Imagem | E20: N/A | F20: Baixa (2) | G20: Alta | I20: A visitar
A21: 19 | B21: Braseiro do Roque | D21: Imagem | E21: Creative | F21: Baixa (2) | G21: Alta | I21: A visitar
A22: 20 | B22: Brazzô Sport Bar | D22: Imagem | E22: Creative | F22: Baixa (2) | G22: Alta | I22: A visitar
A23: 21 | B23: Brewteco | D23: Imagem | E23: Experimenter | F23: Baixa (2) | G23: Alta | I23: A visitar
A24: 22 | B24: Brooks - Méier | C24: Méier | D24: Imagem | E24: Status | F24: Baixa (2) | G24: Alta | I24: A visitar
A25: 23 | B25: Buxixo | D25: Imagem | E25: Experimenter | F25: Baixa (2) | G25: Alta | I25: A visitar
A26: 24 | B26: Calabouço Rock Bar | D26: Imagem | E26: Creative | F26: Baixa (2) | G26: Alta | I26: A visitar
A27: 25 | B27: Casa Nossa Lounge | D27: Imagem | E27: Status-Creative | F27: Baixa (2) | G27: Alta | I27: A visitar
A28: 26 | B28: Classico Beach Club | D28: Imagem | E28: Status | F28: Baixa (2) | G28: Alta | I28: A visitar
A29: 27 | B29: Embrazza | D29: Imagem | E29: Creative | F29: Baixa (2) | G29: Alta | I29: A visitar
A30: 28 | B30: Garota da Tijuca | C30: Tijuca | D30: Imagem | E30: Creative | F30: Baixa (2) | G30: Alta | I30: A visitar
A31: 29 | B31: Hora Certa | D31: Imagem | E31: Experimenter | F31: Baixa (2) | G31: Alta | I31: A visitar
A32: 30 | B32: Jacques | D32: Imagem | E32: Status-Creative | F32: Baixa (2) | G32: Alta | I32: A visitar
A33: 31 | B33: K08 Kite Surf Club | D33: Imagem | E33: Status | F33: Baixa (2) | G33: Alta | I33: A visitar
A34: 32 | B34: Leviano - Lapa | C34: Lapa | D34: Volume | E34: N/A | F34: Baixa (2) | G34: Alta | I34: A visitar
A35: 33 | B35: Mia Lounge | D35: Imagem | E35: Status | F35: Baixa (2) | G35: Alta | I35: A visitar
A36: 34 | B36: Nuth Barra | C36: Barra | D36: Volume | E36: N/A | F36: Baixa (2) | G36: Alta | I36: A visitar
A37: 35 | B37: O Pesqueiro | D37: Imagem | E37: Status | F37: Baixa (2) | G37: Alta | I37: A visitar
A38: 36 | B38: On Tap - tijuca | C38: Tijuca | D38: Imagem | E38: Creative | F38: Baixa (2) | G38: Alta | I38: A visitar
A39: 37 | B39: Pilo's Pub | D39: Imagem | E39: Creative | F39: Baixa (2) | G39: Alta | I39: A visitar
A40: 38 | B40: Pineapple Restaurante | D40: Imagem | E40: Status | F40: Baixa (2) | G40: Alta | I40: A visitar
...

Sheet Rota Semanal
A1: PLANEJAMENTO DE ROTA — decisão do BA. Use o Radar ON6 para escolher os focos, depois monte a rota real da semana.
A2: BA: | C2: Semana de: | E2: Objetivo da semana:
A3: Dia | B3: # | C3: Cliente foco | D3: Bairro / Hotzone | E3: Frente | F3: KPI objetivo | G3: Por que entra na rota | H3: Ação planejada | I3: Material / prep | J3: Status | K3: Resultado / próximo passo
A4: Segunda | B4: #1 | C4: (exemplo) Macuna | D4: Botafoto / Hotzone | E4: Hotzone | F4: Treinamento | G4: Gap ON6 5/6 — falta ativação/treino | H4: Treinar brigada + kit shot | I4: Kit, cardápio, tap | J4: Planejado | K4: Agendar retorno em 15d
A5: Segunda | B5: #1 | J5: Planejado
A6: Segunda | B6: #2 | J6: Planejado
A7: Segunda | B7: #3 | J7: Planejado
A8: Segunda | B8: #4 | J8: Planejado
A9: Segunda | B9: #5 | J9: Planejado
A10: Terça | B10: #1 | J10: Planejado
A11: Terça | B11: #2 | J11: Planejado
A12: Terça | B12: #3 | J12: Planejado
A13: Terça | B13: #4 | J13: Planejado
A14: Terça | B14: #5 | J14: Planejado
A15: Quarta | B15: #1 | J15: Planejado
A16: Quarta | B16: #2 | J16: Planejado
... A29: Sexta | B29: #5 | J29: Planejado

Sheet Aprovação Contratos
A1: APROVAÇÃO DE CONTRATOS — calculadora de investimento. Ideal R$20/gfa · teto R$30/gfa · reserva 25% Tailor Made · saldo 75% fee. Preencha só as células amarelas (volume, meses, invest. solicitado se exceção, prob.).
A2: Região | B2: Cliente | C2: Canal / tipo | D2: Perfil | E2: Energia | F2: Prioridade | G2: Status | H2: Vol/mês | I2: Meses | J2: Vol total | K2: Ideal R$20 | L2: Máx R$30 | M2: Invest. solicitado | N2: Investimento | O2: TM 25% | P2: Fee 75% | Q2: R$/gfa | R2: Parecer | S2: Prob. | T2: Vol pond. | U2: Próximo passo | V2: Owner
A3: RJ | B3: Bosque Bar | C3: Bar/On Trade | D3: Estratégico | E3: 4 | F3: Crítica | G3: Diagnóstico | H3: 80 | I3: 12 | J3: =H3*I3 -> 960 | K3: =J3*20 -> 19200 | L3: =J3*30 -> 28800 | N3: =IF(M3="",K3,M3) -> 19200 | O3: =N3*0.25 -> 4800 | P3: =N3*0.75 -> 14400 | Q3: =IF(J3=0,"",N3/J3) -> 20 | R3: =IF(J3=0,"—",IF(N3/J3<=20,"OK ideal",IF(N3/J3<=30,"Dentro do teto","Acima do teto"))) -> OK ideal | S3: 0.35 | T3: =J3*S3 -> 336 | U3: Atualizar negociação, definir budget e avançar briefing/TM | V3: Bruno
A4: RJ | B4: Ephigenia | C4: Bar/On Trade | D4: Imagem + Volume | E4: 4 | F4: Alta | G4: Negociação | H4: 70 | I4: 12 | J4: =H4*I4 -> 840 | K4: =J4*20 -> 16800 | L4: =J4*30 -> 25200 | N4: =IF(M4="",K4,M4) -> 16800 | O4: =N4*0.25 -> 4200 | P4: =N4*0.75 -> 12600 | Q4: =IF(J4=0,"",N4/J4) -> 20 | R4: =IF(J4=0,"—",IF(N4/J4<=20,"OK ideal",IF(N4/J4<=30,"Dentro do teto","Acima do teto"))) -> OK ideal | S4: 0.4 | T4: =J4*S4 -> 336 | U4: Reunião contratual e briefing completo para Tanize | V4: Bruno
A5: RJ | B5: Amargot | C5: Bar/On Trade | D5: Imagem | E5: 3 | F5: Média | G5: Diagnóstico | H5: 30 | I5: 12 | J5: =H5*I5 -> 360 | K5: =J5*20 -> 7200 | L5: =J5*30 -> 10800 | N5: =IF(M5="",K5,M5) -> 7200 | O5: =N5*0.25 -> 1800 | P5: =N5*0.75 -> 5400 | Q5: =IF(J5=0,"",N5/J5) -> 20 | R5: =IF(J5=0,"—",IF(N5/J5<=20,"OK ideal",IF(N5/J5<=30,"Dentro do teto","Acima do teto"))) -> OK ideal | S5: 0.3 | T5: =J5*S5 -> 108 | U5: Atualizar negociação e definir escopo do novo TM | V5: Bruno
A6: RJ | B6: Pato com Laranja | C6: Restaurante premium | D6: Evento/Festival | E6: 4 | F6: Alta | G6: Negociação | I6: 12 | J6: =H6*I6 -> 0 | K6: =J6*20 -> 0 | L6: =J6*30 -> 0 | N6: =IF(M6="",K6,M6) -> 0 | O6: =N6*0.25 -> 0 | P6: =N6*0.75 -> 0 | Q6: =IF(J6=0,"",N6/J6) | R6: =IF(J6=0,"—",IF(N6/J6<=20,"OK ideal",IF(N6/J6<=30,"Dentro do teto","Acima do teto"))) -> — | S6: 0.55 | T6: =J6*S6 -> 0 | U6: Confirmar guest, treino, DJ, materiais e experiência | V6: Bruno/Jerry
A7: RJ | B7: Arpbar | C7: Bar/On Trade | D7: Teste | E7: 3 | F7: Média | G7: Mapeado | I7: 12 | J7: =H7*I7 -> 0 | K7: =J7*20 -> 0 | L7: =J7*30 -> 0 | N7: =IF(M7="",K7,M7) -> 0 | O7: =N7*0.25 -> 0 | P7: =N7*0.75 -> 0 | Q7: =IF(J7=0,"",N7/J7) | R7: =IF(J7=0,"—",IF(N7/J7<=20,"OK ideal",IF(N7/J7<=30,"Dentro do teto","Acima do teto"))) -> — | S7: 0.25 | T7: =J7*S7 -> 0 | U7: Confirmar viabilidade da casa para ativação | V7: Bruno
A8: RJ | B8: Casa Lagoa / Grupo Lagoa | C8: Grupo On Trade | D8: Imagem + Volume | E8: 4 | F8: Alta | G8: Mapeado | I8: 12 | J8: =H8*I8 -> 0 | K8: =J8*20 -> 0 | L8: =J8*30 -> 0 | N8: =IF(M8="",K8,M8) -> 0 | O8: =N8*0.25 -> 0 | P8: =N8*0.75 -> 0 | Q8: =IF(J8=0,"",N8/J8) | R8: =IF(J8=0,"—",IF(N8/J8<=20,"OK ideal",IF(N8/J8<=30,"Dentro do teto","Acima do teto"))) -> — | S8: 0.35 | T8: =J8*S8 -> 0 | U8: Mapear casas do grupo e proposta por unidade | V8: Bruno
A9: RJ | B9: Sweet Secrets | C9: Bar/Experiência | D9: Imagem | E9: 4 | F9: Alta | G9: Negociação | I9: 12 | J9: =H9*I9 -> 0 | K9: =J9*20 -> 0 | L9: =J9*30 -> 0 | N9: =IF(M9="",K9,M9) -> 0 | O9: =N9*0.25 -> 0 | P9: =N9*0.75 -> 0 | Q9: =IF(J9=0,"",N9/J9) | R9: =IF(J9=0,"—",IF(N9/J9<=20,"OK ideal",IF(N9/J9<=30,"Dentro do teto","Acima do teto"))) -> — | S9: 0.4 | T9: =J9*S9 -> 0 | U9: Avançar parceria e conectar a conteúdo/experiência | V9: Bruno
A10: RJ | B10: Canastra / Canastra Rosé | C10: Bar/On Trade | D10: Imagem + Volume | E10: 4 | F10: Alta | G10: Negociação | I10: 12 | J10: =H10*I10 -> 0 | K10: =J10*20 -> 0 | L10: =J10*30 -> 0 | N10: =IF(M10="",K10,M10) -> 0 | O10: =N10*0.25 -> 0 | P10: =N10*0.75 -> 0 | Q10: =IF(J10=0,"",N10/J10) | R10: =IF(J10=0,"—",IF(N10/J10<=20,"OK ideal",IF(N10/J10<=30,"Dentro do teto","Acima do teto"))) -> — | S10: 0.45 | T10: =J10*S10 -> 0 | U10: Definir formato de consumo para carnaval/verão | V10: Bruno
A11: RJ | B11: Caledonia | C11: Bar/On Trade | D11: Imagem | E11: 4 | F11: Alta | G11: Mapeado | I11: 12 | J11: =H11*I11 -> 0 | K11: =J11*20 -> 0 | L11: =J11*30 -> 0 | N11: =IF(M11="",K11,M11) -> 0 | O11: =N11*0.25 -> 0 | P11: =N11*0.75 -> 0 | Q11: =IF(J11=0,"",N11/J11) | R11: =IF(J11=0,"—",IF(N11/J11<=20,"OK ideal",IF(N11/J11<=30,"Dentro do teto","Acima do teto"))) -> — | S11: 0.3 | T11: =J11*S11 -> 0 | U11: Entrar via Interfood e avaliar Manifest | V11: Bruno
A12: RJ | B12: Elena Horto | C12: Bar/Alta coquetelaria | D12: Imagem | E12: 5 | F12: Alta | G12: Mapeado | I12: 12 | J12: =H12*I12 -> 0 | K12: =J12*20 -> 0 | L12: =J12*30 -> 0 | N12: =IF(M12="",K12,M12) -> 0 | O12: =N12*0.25 -> 0 | P12: =N12*0.75 -> 0 | Q12: =IF(J12=0,"",N12/J12) | R12: =IF(J12=0,"—",IF(N12/J12<=20,"OK ideal",IF(N12/J12<=30,"Dentro do teto","Acima do teto"))) -> — | S12: 0.35 | T12: =J12*S12 -> 0 | U12: Avaliar guest/masterclass e Manifest/Teremana | V12: Bruno
A13: RJ | B13: Murdock | C13: Bar/On Trade | D13: Imagem | E13: 4 | F13: Alta | G13: Mapeado | I13: 12 | J13: =H13*I13 -> 0 | K13: =J13*20 -> 0 | L13: =J13*30 -> 0 | N13: =IF(M13="",K13,M13) -> 0 | O13: =N13*0.25 -> 0 | P13: =N13*0.75 -> 0 | Q13: =IF(J13=0,"",N13/J13) | R13: =IF(J13=0,"—",IF(N13/J13<=20,"OK ideal",IF(N13/J13<=30,"Dentro do teto","Acima do teto"))) -> — | S13: 0.3 | T13: =J13*S13 -> 0 | U13: Usar contato do Vitor, validar Manifest premium | V13: Bruno/Vitor
A14: RJ | B14: Europa Lounge | C14: Bar/On Trade | D14: Imagem | E14: 4 | F14: Alta | G14: Mapeado | I14: 12 | J14: =H14*I14 -> 0 | K14: =J14*20 -> 0 | L14: =J14*30 -> 0 | N14: =IF(M14="",K14,M14) -> 0 | O14: =N14*0.25 -> 0 | P14: =N14*0.75 -> 0 | Q14: =IF(J14=0,"",N14/J14) | R14: =IF(J14=0,"—",IF(N14/J14<=20,"OK ideal",IF(N14/J14<=30,"Dentro do teto","Acima do teto"))) -> — | S14: 0.3 | T14: =J14*S14 -> 0 | U14: Usar contato do Vitor e avaliar fit Manifest | V14: Bruno/Vitor
A15: RJ | B15: Circo Voador | C15: Casa de show | D15: Eventos | E15: 4 | F15: Alta | G15: Diagnóstico | I15: 12 | J15: =H15*I15 -> 0 | K15: =J15*20 -> 0 | L15: =J15*30 -> 0 | N15: =IF(M15="",K15,M15) -> 0 | O15: =N15*0.25 -> 0 | P15: =N15*0.75 -> 0 | Q15: =IF(J15=0,"",N15/J15) | R15: =IF(J15=0,"—",IF(N15/J15<=20,"OK ideal",IF(N15/J15<=30,"Dentro do teto","Acima do teto"))) -> — | S15: 0.4 | T15: =J15*S15 -> 0 | U15: Revisar contrato existente e corrigir execução | V15: Bruno
A16: RJ | B16: Aldeia | C16: Bar/On Trade | D16: Imagem + Volume | E16: 4 | F16: Alta | G16: Fechado | I16: 12 | J16: =H16*I16 -> 0 | K16: =J16*20 -> 0 | L16: =J16*30 -> 0 | N16: =IF(M16="",K16,M16) -> 0 | O16: =N16*0.25 -> 0 | P16: =N16*0.75 -> 0 | Q16: =IF(J16=0,"",N16/J16) | R16: =IF(J16=0,"—",IF(N16/J16<=20,"OK ideal",IF(N16/J16<=30,"Dentro do teto","Acima do teto"))) -> — | S16: 0.35 | T16: =J16*S16 -> 0 | U16: Priorizar execução e contrapartida | V16: Bruno
A17: RJ | B17: Caza Lagoa | C17: Bar/On Trade | D17: Imagem + Volume | E17: 4 | F17: Alta | G17: Fechado | I17: 12 | J17: =H17*I17 -> 0 | K17: =J17*20 -> 0 | L17: =J17*30 -> 0 | N17: =IF(M17="",K17,M17) -> 0 | O17: =N17*0.25 -> 0 | P17: =N17*0.75 -> 0 | Q17: =IF(J17=0,"",N17/J17) | R17: =IF(J17=0,"—",IF(N17/J17<=20,"OK ideal",IF(N17/J17<=30,"Dentro do teto","Acima do teto"))) -> — | S17: 0.35 | T17: =J17*S17 -> 0 | U17: Priorizar execução e contrapartida | V17: Bruno
... A22: RJ | B22: Rigarr | C22: Distribuidor | D22: Volume | E22: 3 | F22: Alta | G22: Mapeado | I22: 12 | J22: =H22*I22 -> 0 | K22: =J22*20 -> 0 | L22: =J22*30 -> 0 | N22: =IF(M22="",K22,M22) -> 0 | O22: =N22*0.25 -> 0 | P22: =N22*0.75 -> 0 | Q22: =IF(J22=0,"",N22/J22) | R22: =IF(J22=0,"—",IF(N22/J22<=20,"OK ideal",IF(N22/J22<=30,"Dentro do teto","Acima do teto"))) -> — | S22: 0.5 | T22: =J22*S22 -> 0 | U22: Estruturar conta corrente/boni antecipada | V22: Bruno
A23: RJ | B23: Camisa 10 | C23: Evento/Carnaval | D23: Evento/Festival | E23: 4 | F23: Alta | G23: Negociação | H23: 100 | I23: 12 | J23: =H23*I23 -> 1200 | K23: =J23*20 -> 24000 | L23: =J23*30 -> 36000 | N23: =IF(M23="",K23,M23) -> 24000 | O23: =N23*0.25 -> 6000 | P23: =N23*0.75 -> 18000 | Q23: =IF(J23=0,"",N23/J23) -> 20 | R23: =IF(J23=0,"—",IF(N23/J23<=20,"OK ideal",IF(N23/J23<=30,"Dentro do teto","Acima do teto"))) -> OK ideal | S23: 0.45 | T23: =J23*S23 -> 540 | U23: Fechar 100gfas + R$10k + exposição + ingressos | V23: Bruno
A24: RJ | B24: Aura | C24: Evento/Carnaval | D24: Evento/Festival | E24: 4 | F24: Alta | G24: Negociação | I24: 12 | J24: =H24*I24 -> 0 | K24: =J24*20 -> 0 | L24: =J24*30 -> 0 | N24: =IF(M24="",K24,M24) -> 0 | O24: =N24*0.25 -> 0 | P24: =N24*0.75 -> 0 | Q24: =IF(J24=0,"",N24/J24) | R24: =IF(J24=0,"—",IF(N24/J24<=20,"OK ideal",IF(N24/J24<=30,"Dentro do teto","Acima do teto"))) -> — | S24: 0.4 | T24: =J24*S24 -> 0 | U24: Priorizar; R$10k + boni condicionada + ativação | V24: Bruno
A25: RJ | B25: Camarote Mar | C25: Evento/Carnaval | D25: Evento/Festival | E25: 4 | F25: Alta | G25: Negociação | I25: 12 | J25: =H25*I25 -> 0 | K25: =J25*20 -> 0 | L25: =J25*30 -> 0 | N25: =IF(M25="",K25,M25) -> 0 | O25: =N25*0.25 -> 0 | P25: =N25*0.75 -> 0 | Q25: =IF(J25=0,"",N25/J25) | R25: =IF(J25=0,"—",IF(N25/J25<=20,"OK ideal",IF(N25/J25<=30,"Dentro do teto","Acima do teto"))) -> — | S25: 0.5 | T25: =J25*S25 -> 0 | U25: Consolidar contrapartidas e volume bonificado | V25: Bruno
A26: SP | B26: Tokyo | C26: Casa noturna | D26: Imagem + Volume | E26: 5 | F26: Crítica | G26: Negociação | H26: 110 | I26: 12 | J26: =H26*I26 -> 1320 | K26: =J26*20 -> 26400 | L26: =J26*30 -> 39600 | N26: =IF(M26="",K26,M26) -> 26400 | O26: =N26*0.25 -> 6600 | P26: =N26*0.75 -> 19800 | Q26: =IF(J26=0,"",N26/J26) -> 20 | R26: =IF(J26=0,"—",IF(N26/J26<=20,"OK ideal",IF(N26/J26<=30,"Dentro do teto","Acima do teto"))) -> OK ideal | S26: 0.45 | T26: =J26*S26 -> 594 | U26: Visita, subir máquina, ativar bar inferior e TM fixo | V26: João/Bruno
A27: SP | B27: Martinelli | C27: Grupo/Rede | D27: Rede/Grupo | E27: 4 | F27: Alta | G27: Diagnóstico | H27: 120 | I27: 12 | J27: =H27*I27 -> 1440 | K27: =J27*20 -> 28800 | L27: =J27*30 -> 43200 | N27: =IF(M27="",K27,M27) -> 28800 | O27: =N27*0.25 -> 7200 | P27: =N27*0.75 -> 21600 | Q27: =IF(J27=0,"",N27/J27) -> 20 | R27: =IF(J27=0,"—",IF(N27/J27<=20,"OK ideal",IF(N27/J27<=30,"Dentro do teto","Acima do teto"))) -> OK ideal | S27: 0.4 | T27: =J27*S27 -> 576 | U27: Reforma carrinho, ponto fixo e visita com Tanize | V27: Bruno/Tanize
A28: SP | B28: Evva Club | C28: Casa noturna | D28: Volume | E28: 4 | F28: Alta | G28: Proposta | I28: 12 | J28: =H28*I28 -> 0 | K28: =J28*20 -> 0 | L28: =J28*30 -> 0 | N28: =IF(M28="",K28,M28) -> 0 | O28: =N28*0.25 -> 0 | P28: =N28*0.75 -> 0 | Q28: =IF(J28=0,"",N28/J28) | R28: =IF(J28=0,"—",IF(N28/J28<=20,"OK ideal",IF(N28/J28<=30,"Dentro do teto","Acima do teto"))) -> — | S28: 0.7 | T28: =J28*S28 -> 0 | U28: Enviar proposta formal e estruturar TM/materiais | V28: Bruno
A29: SP | B29: Deus Ex Machina | C29: Bar/On Trade | D29: Imagem + Volume | E29: 4 | F29: Alta | G29: Proposta | I29: 12 | J29: =H29*I29 -> 0 | K29: =J29*20 -> 0 | L29: =J29*30 -> 0 | N29: =IF(M29="",K29,M29) -> 0 | O29: =N29*0.25 -> 0 | P29: =N29*0.75 -> 0 | Q29: =IF(J29=0,"",N29/J29) | R29: =IF(J29=0,"—",IF(N29/J29<=20,"OK ideal",IF(N29/J29<=30,"Dentro do teto","Acima do teto"))) -> — | S29: 0.45 | T29: =J29*S29 -> 0 | U29: Retomar proposta PPT e estruturar introdução | V29: Bruno
A30: SP | B30: Amata | C30: Bar/On Trade | D30: Imagem + Volume | E30: 3 | F30: Alta | G30: Diagnóstico | I30: 12 | J30: =H30*I30 -> 0 | K30: =J30*20 -> 0 | L30: =J30*30 -> 0 | N30: =IF(M30="",K30,M30) -> 0 | O30: =N30*0.25 -> 0 | P30: =N30*0.75 -> 0 | Q30: =IF(J30=0,"",N30/J30) | R30: =IF(J30=0,"—",IF(N30/J30<=20,"OK ideal",IF(N30/J30<=30,"Dentro do teto","Acima do teto"))) -> — | S30: 0.35 | T30: =J30*S30 -> 0 | U30: Revisar execução e plano de ativação | V30: João/Bruno
A31: SP | B31: MEAW Club | C31: Club/LGBT | D31: Volume | E31: 5 | F31: Crítica | G31: Prospecção | I31: 12 | J31: =H31*I31 -> 0 | K31: =J31*20 -> 0 | L31: =J31*30 -> 0 | N31: =IF(M31="",K31,M31) -> 0 | O31: =N31*0.25 -> 0 | P31: =N31*0.75 -> 0 | Q31: =IF(J31=0,"",N31/J31) | R31: =IF(J31=0,"—",IF(N31/J31<=20,"OK ideal",IF(N31/J31<=30,"Dentro do teto","Acima do teto"))) -> — | S31: 0.45 | T31: =J31*S31 -> 0 | U31: Fechar contrato e montar execução (Jäger+RB) | V31: João/Bruno
A32: SP | B32: High Club | C32: Club/LGBT | D32: Volume | E32: 5 | F32: Alta | G32: Mapeado | I32: 12 | J32: =H32*I32 -> 0 | K32: =J32*20 -> 0 | L32: =J32*30 -> 0 | N32: =IF(M32="",K32,M32) -> 0 | O32: =N32*0.25 -> 0 | P32: =N32*0.75 -> 0 | Q32: =IF(J32=0,"",N32/J32) | R32: =IF(J32=0,"—",IF(N32/J32<=20,"OK ideal",IF(N32/J32<=30,"Dentro do teto","Acima do teto"))) -> — | S32: 0.35 | T32: =J32*S32 -> 0 | U32: Avaliar contrato de volume no território LGBT | V32: João/Bruno
A33: SP | B33: Clube Jerome | C33: Club/LGBT | D33: Volume | E33: 5 | F33: Alta | G33: Mapeado | I33: 12 | J33: =H33*I33 -> 0 | K33: =J33*20 -> 0 | L33: =J33*30 -> 0 | N33: =IF(M33="",K33,M33) -> 0 | O33: =N33*0.25 -> 0 | P33: =N33*0.75 -> 0 | Q33: =IF(J33=0,"",N33/J33) | R33: =IF(J33=0,"—",IF(N33/J33<=20,"OK ideal",IF(N33/J33<=30,"Dentro do teto","Acima do teto"))) -> — | S33: 0.35 | T33: =J33*S33 -> 0 | U33: Avaliar contrato de volume no território LGBT | V33: João/Bruno
A34: SP | B34: Arlette | C34: Bar/On Trade | D34: Imagem + Volume | E34: 4 | F34: Alta | G34: Mapeado | I34: 12 | J34: =H34*I34 -> 0 | K34: =J34*20 -> 0 | L34: =J34*30 -> 0 | N34: =IF(M34="",K34,M34) -> 0 | O34: =N34*0.25 -> 0 | P34: =N34*0.75 -> 0 | Q34: =IF(J34=0,"",N34/J34) | R34: =IF(J34=0,"—",IF(N34/J34<=20,"OK ideal",IF(N34/J34<=30,"Dentro do teto","Acima do teto"))) -> — | S34: 0.35 | T34: =J34*S34 -> 0 | U34: Fomentar drinks e presença em cardápio | V34: João/Bruno
A35: SP | B35: Vila Dionisio | C35: Bar/On Trade | D35: Volume | E35: 3 | F35: Média | G35: Mapeado | I35: 12 | J35: =H35*I35 -> 0 | K35: =J35*20 -> 0 | L35: =J35*30 -> 0 | N35: =IF(M35="",K35,M35) -> 0 | O35: =N35*0.25 -> 0 | P35: =N35*0.75 -> 0 | Q35: =IF(J35=0,"",N35/J35) | R35: =IF(J35=0,"—",IF(N35/J35<=20,"OK ideal",IF(N35/J35<=30,"Dentro do teto","Acima do teto"))) -> — | S35: 0.25 | T35: =J35*S35 -> 0 | U35: Definir ação, decisor e próximos passos | V35: Bruno
A36: SP | B36: Giardino | C36: Restaurante premium | D36: Imagem | E36: 3 | F36: Média | G36: Mapeado | I36: 12 | J36: =H36*I36 -> 0 | K36: =J36*20 -> 0 | L36: =J36*30 -> 0 | N36: =IF(M36="",K36,M36) -> 0 | O36: =N36*0.25 -> 0 | P36: =N36*0.75 -> 0 | Q36: =IF(J36=0,"",N36/J36) | R36: =IF(J36=0,"—",IF(N36/J36<=20,"OK ideal",IF(N36/J36<=30,"Dentro do teto","Acima do teto"))) -> — | S36: 0.25 | T36: =J36*S36 -> 0 | U36: Definir atividade e possibilidade de contrato | V36: Bruno
A37: SP | B37: Casa Rockambole | C37: Bar/On Trade | D37: Imagem | E37: 3 | F37: Média | G37: Diagnóstico | I37: 12 | J37: =H37*I37 -> 0 | K37: =J37*20 -> 0 | L37: =J37*30 -> 0 | N37: =IF(M37="",K37,M37) -> 0 | O37: =N37*0.25 -> 0 | P37: =N37*0.75 -> 0 | Q37: =IF(J37=0,"",N37/J37) | R37: =IF(J37=0,"—",IF(N37/J37<=20,"OK ideal",IF(N37/J37<=30,"Dentro do teto","Acima do teto"))) -> — | S37: 0.25 | T37: =J37*S37 -> 0 | U37: Levantar status do investimento e decidir | V37: João/Bruno
A38: SP | B38: Cine Clube Cortina | C38: Bar/On Trade | D38: Imagem | E38: 3 | F38: Média | G38: Diagnóstico | I38: 12 | J38: =H38*I38 -> 0 | K38: =J38*20 -> 0 | L38: =J38*30 -> 0 | N38: =IF(M38="",K38,M38) -> 0 | O38: =N38*0.25 -> 0 | P38: =N38*0.75 -> 0 | Q38: =IF(J38=0,"",N38/J38) | R38: =IF(J38=0,"—",IF(N38/J38<=20,"OK ideal",IF(N38/J38<=30,"Dentro do teto","Acima do teto"))) -> — | S38: 0.25 | T38: =J38*S38 -> 0 | U38: Avaliar oportunidade real de cardápio/ritual | V38: João/Bruno
A39: SP | B39: Doisdois | C39: Bar/On Trade | D39: Imagem + Volume | E39: 3 | F39: Média | G39: Diagnóstico | I39: 12 | J39: =H39*I39 -> 0 | K39: =J39*20 -> 0 | L39: =J39*30 -> 0 | N39: =IF(M39="",K39,M39) -> 0 | O39: =N39*0.25 -> 0 | P39: =N39*0.75 -> 0 | Q39: =IF(J39=0,"",N39/J39) | R39: =IF(J39=0,"—",IF(N39/J39<=20,"OK ideal",IF(N39/J39<=30,"Dentro do teto","Acima do teto"))) -> — | S39: 0.25 | T39: =J39*S39 -> 0 | U39: Entender status e potencial de consumo | V39: João/Bruno
... A41: SP | B41: Village | C41: Evento/Carnaval | D41: Eventos | E41: 3 | F41: Alta | G41: Mapeado | I41: 12 | J41: =H41*I41 -> 0 | K41: =J41*20 -> 0 | L41: =J41*30 -> 0 | N41: =IF(M41="",K41,M41) -> 0 | O41: =N41*0.25 -> 0 | P41: =N41*0.75 -> 0 | Q41: =IF(J41=0,"",N41/J41) | R41: =IF(J41=0,"—",IF(N41/J41<=20,"OK ideal",IF(N41/J41<=30,"Dentro do teto","Acima do teto"))) -> — | S41: 0.3 | T41: =J41*S41 -> 0 | U41: Revisar ativação, promotora, report e saída | V41: Bruno
A43: RESUMO
A44: Casas no pipeline | B44: Volume total projetado (gf) | C44: Investimento (ideal/aprovado) | D44: Reserva Tailor Made 25% | E44: Saldo fee 75% | F44: Volume ponderado (forecast) | G44: Contratos fechados
A45: =COUNTA(B3:B41) -> 39 | B45: =SUM(J3:J41) -> 6120 | C45: =SUM(N3:N41) -> 122400 | D45: =SUM(O3:O41) -> 30600 | E45: =SUM(P3:P41) -> 91800 | F45: =SUM(T3:T41) -> 2490 | G45: =COUNTIF(G3:G41,"Fechado") -> 2

Sheet Parâmetros Contrato
A1: PARÂMETROS DO MODELO DE CONTRATOS
A2: Base do racional acordado com Vitor. Não editar em contratos individuais — mudar aqui só se a política mudar.
A4: Regra central
A5: Investimento ideal por garrafa | B5: R$ 20 | C5: Âncora de negociação
A6: Investimento máximo por garrafa | B6: R$ 30 | C6: Teto — só com contrapartida forte
A7: Reserva Tailor Made / Experiências | B7: 25% | C7: Separar antes de fee/TM/eventos
A8: Saldo Fee + TM + Eventos | B8: 75% | C8: Distribuído pelo perfil
A9: Prazo padrão | B9: 12 meses | C9: Ajustar se contrato diferente
A11: Distribuição do saldo por perfil
A12: Perfil | B12: Fee % | C12: TM % | D12: Eventos % | E12: Fator
A13: Volume | B13: 0.45 | C13: 0.35 | D13: 0.2 | E13: 0.95
A14: Imagem | B14: 0.25 | C14: 0.35 | D14: 0.4 | E14: 1
A15: Misto | B15: 0.35 | C15: 0.3 | D15: 0.35 | E15: 1
A16: Estratégico | B16: 0.3 | C16: 0.25 | D16: 0.45 | E16: 1.05
A17: Evento/Festival | B17: 0.2 | C17: 0.2 | D17: 0.6 | E17: 1
A18: Rede/Grupo | B18: 0.4 | C18: 0.35 | D18: 0.25 | E18: 0.95
A19: Teste | B19: 0.2 | C19: 0.5 | D19: 0.3 | E19: 0.8
A20: Imagem + Volume | B20: 0.32 | C20: 0.28 | D20: 0.4 | E20: 1.05
A22: Fator energia | D22: Fator prioridade
A23: 1 fria | B23: 0.6 | D23: Baixa | E23: 0.7
A24: 2 | B24: 0.7 | D24: Média | E24: 0.85
A25: 3 observação | B25: 0.8 | D25: Alta | E25: 1
A26: 4 | B26: 0.9 | D26: Crítica | E26: 1.1
A27: 5 forte | B27: 1
A29: Faixas de volume (referência)
A30: cx/mês | B30: cx/tri | C30: Ideal anual R$20 | D30: Máx anual R$30 | E30: Reserva 25%
A31: 25 | B31: 75 | C31: 6000 | D31: 9000 | E31: 1500
A32: 50 | B32: 150 | C32: 12000 | D32: 18000 | E32: 3000
A33: 75 | B33: 225 | C33: 18000 | D33: 27000 | E33: 4500
A34: 100 | B34: 300 | C34: 24000 | D34: 36000 | E34: 6000
A35: 125 | B35: 375 | C35: 30000 | D35: 45000 | E35: 7500
A36: 150 | B36: 450 | C36: 36000 | D36: 54000 | E36: 9000
A37: 175 | B37: 525 | C37: 42000 | D37: 63000 | E37: 10500
A38: 200 | B38: 600 | C38: 48000 | D38: 72000 | E38: 12000
A39: 225 | B39: 675 | C39: 54000 | D39: 81000 | E39: 13500
A40: 250 | B40: 750 | C40: 60000 | D40: 90000 | E40: 15000
A42: Arquétipos de investimento (bonificação/base)
A43: Cliente Imagem & Volume | B43: R$ 5.000 | C43: Novo estratégico: cardápio, publicações, ativações
A44: Cliente Volume | B44: R$ 2.000 | C44: Conta de giro/volume
A45: Cliente Imagem | B45: R$ 2.000 | C45: Conta de imagem
...
